Workbook

Sheet Sheet1
B3: 1 | C3: Raw material | E3: 2 | F3: packaging | H3: 3 | I3: maintenance | K3: 4 | L3: car expenses | N3: 5 | O3: Car Rental and transportation
B4: 1-A | C4: Food ingredients | E4: 2-A | F4: Takeaway boxes | H4: 3-A | I4: Kitchen Equipment Maintenance | K4: 4-A | L4: Car maintenance | N4: 5-A | O4: car rent
C5: Meat | F5: Cups | I5: Building Maintenance | L5: Oil changes
C6: Chicken | F6: Lids | I6: Electrical Repairs | L6: Tire replacement and repairs | N6: 5-B | O6: Fuel Expense
C7: Fish & seafood | F7: Bags | I7: Plumbing Repairs | L7: Brake repairs
C8: Vegetables & fruits | F8: Napkins | I8: (A/C) Maintenance | L8: Battery replacement | N8: 5-C | O8: Transportation
C9: Rice, flour, pasta | F9: Disposable cutlery | I9: Furniture Repairs | L9: Engine repairs | O9: Parking Fees
C10: Dairy products | I10: pest control | L10: Regular servicing | O10: Delivery Vehicle Expenses
C11: Spices & seasonings | E11: 2-B | F11: Floor cleaner | I11: fire alarm | L11: Car wash (if expensed) | O11: Uber
F12: Dishwashing liquid | L12: Vehicle spare parts | O12: Freight and Local Transport
B13: 1-B | C13: Beverages | F13: Kitchen degreaser
C14: Soft drinks | F14: Bathroom cleaner | K14: 4-B | L14: Vehicle Insurance
C15: Juices | F15: Mops, brooms, brushes
C16: Coffee & tea | F16: Trash bags | K16: 4-C | L16: Vehicle Registration
C17: Water | F17: Hand soap
B19: 6 | C19: Direct expenses | E19: 7 | F19: Rent | H19: 8 | I19: Salaries | K19: 9 | L19: Bonus and allowance | N19: 10 | O19: Marketing
B20: 6-A | C20: Cooking gas | F20: Restaurant rent | H20: 8-A | I20: Management salaries | K20: 9-A | L20: Overtime | N20: 10-A | O20: Marketing & Advertising Expenses
F21: Kitchen rent | O21: Online Advertising
B22: 6-B | C22: Charcoal for grills/BBQ | F22: Storage/warehouse rent | K22: 9- B | L22: Bonus | O22: Social Media Marketing
F23: Office rent | H23: 8-B | I23: Admin staff salaries | O23: Promotions
K24: 9-C | L24: Allowances | O24: Printing & Design
L25: Housing Allowance | O25: Campaign Expenses
H26: 8-C | I26: Accounting/office salaries | L26: Transportation Allowance
L27: Meal Allowance
L28: Other Staff Allowances
B30: 11 | C30: Kahrama | E30: 12 | F30: Bank charge | H30: 13 | I30: stationery | K30: 14 | L30: Utilities | N30: 15 | O30: Government fees
B31: 11-A | C31: Electricity Expense | F31: Bank account fees | H31: 13-A | I31: Stationery Expense | K31: 14-A | L31: Mobile phone bills | O31: License Fees
F32: POS machine fees | O32: Permit Fees
B33: 11-B | C33: Water Expense | F33: Transfer fees | H33: 13-B | I33: Office Supplies | K33: 14-B | L33: Internet bills | O33: Municipality Fees
F34: Cheque fees | O34: Other Government Charges
F35: Other bank service charges | H35: 13-C | I35: Printing Expense | K35: 14-C | L35: Landline bills
F36: interest loan
B38: 16 | C38: Ticket and Traveling | E38: 17 | F38: Professional Fees | H38: 18 | I38: office expenses | K38: 19 | L38: Other Expenses ( indirect )
C39: Travel & Transportation | F39: Financial Consulting Fees | I39: Office Furniture (small purchases) | L39: Small business expenses not classified elsewhere
C40: Air Ticket Expense | F40: Legal Consulting Fees | L40: Gifts & Appreciation
C41: Hotel Expense | F41: Accounting Fees | I41: Software & Subscriptions | L41: Other unusual expenses
C42: Business Travel Expense | F42: Audit Fees | L42: Emergency Expenses
C43: Local Transport Expense | F43: Tax Consultancy Fees | I43: Office Maintenance | L43: Losses on disposal of assets
F44: Lawyer Fees | L44: Customer Compensation
F45: Business Advisory Fees | I45: Office Cleaning | L45: Donations
...

Sheet July 2026
B1: =SUM(C137:AG137) -> 149692.73 | C1: 46204
A2: 1 | B2: Raw material | C2: 46204 | D2: 46205 | E2: 46206 | F2: 46207 | G2: 46208 | H2: 46209 | I2: 46210 | J2: 46211 | K2: 46212 | L2: 46213 | M2: 46214 | N2: 46215 | O2: 46216 | P2: 46217 | Q2: 46218 | R2: 46219 | S2: 46220 | T2: 46221 | U2: 46222 | V2: 46223 | W2: 46224 | X2: 46225 | Y2: 46226 | Z2: 46227 | AA2: 46228 | AB2: 46229 | AC2: 46230 | AD2: 46231 | AE2: 46232 | AF2: 46233 | AG2: 46234
A3: 1-A | B3: Food ingredients | C3: =94+21+43+20+22+5+156+100+723 -> 1184 | D3: =58+77+299+5+35+129+80+710+377+122+680+633+34 -> 3239 | E3: =24+70+69+59+5+20+150 -> 397 | F3: =20+4+225+1327+478+662 -> 2716 | G3: =36+580+246+231+107 -> 1200 | H3: =6625+595+20+20+311+125+124+661+660+72+139 -> 9352 | I3: =68+74+57+68+800 -> 1067 | J3: =270+57+150+169+40 -> 686 | K3: =172+32.4+225 -> 429.4 | L3: 34 | M3: =70+119+17+413+325+162+64+94+539+265+379 -> 2447 | N3: =32+120 -> 152 | O3: =170+357.5 -> 527.5 | P3: =152+5+120 -> 277 | Q3: =20+82+15+103.64+14 -> 234.64 | R3: =10+155+79.25+215.76+110 -> 570.01 | S3: 101.5 | T3: =69.5+120.75+30+53.5+212.75+308 -> 794.5 | U3: =53.25+28.5 -> 81.75 | V3: =30+18 -> 48 | W3: =25+1530+70+56.5+125 -> 1806.5 | X3: =58+56.25+10.5+19.5+224+1317 -> 1685.25 | Y3: =12+24+41+504 -> 581 | AA3: =20+105.86+233.6+95.88+135 -> 590.34 | AB3: =26+139+56+160+85+132.98 -> 598.98 | AC3: 112 | AD3: =80+46+38.5+182 -> 346.5 | AE3: =120+50+107.45+24+150+90+280+38.25+1408+917 -> 3184.7 | AF3: =47+10.5+55+340 -> 452.5 | AG3: 55 | AH3: =SUM(C3:AG3) -> 34951.07
B4: Meat | N4: 787.02 | U4: 513.5 | W4: 602.32 | Y4: 331.55 | AC4: 230 | AH4: =SUM(C4:AG4) -> 2464.39
B5: Chicken | W5: 1320 | AC5: 155 | AH5: =SUM(C5:AG5) -> 1475
B6: Fish & seafood | N6: 660 | AH6: =SUM(C6:AG6) -> 660
B7: Vegetables & fruits | F7: 3000 | M7: 4000 | AH7: =SUM(C7:AG7) -> 7000
B8: Rice, flour, pasta | AH8: =SUM(C8:AG8) -> 0
B9: Dairy products | AH9: =SUM(C9:AG9) -> 0
B10: Spices & seasonings | AH10: =SUM(C10:AG10) -> 0
A11: 1-B | B11: Beverages | AH11: =SUM(C11:AG11) -> 0
B12: Soft drinks | C12: 975 | AC12: 823 | AH12: =SUM(C12:AG12) -> 1798
B13: Juices | AH13: =SUM(C13:AG13) -> 0
B14: Coffee & tea | AH14: =SUM(C14:AG14) -> 0
B15: Water | C15: 450 | AH15: =SUM(C15:AG15) -> 450
A16: 2 | B16: packaging | D16: =52+138 -> 190 | H16: 299 | K16: =115+131+48.5+38+65+10 -> 407.5 | L16: =66 -> 66 | N16: 70 | Q16: =158+65+140 -> 363 | R16: 205 | W16: =50+93.5 -> 143.5 | AC16: 309 | AD16: 185 | AF16: 3 | AH16: =SUM(C16:AG16) -> 2241
A17: 2-A | B17: Takeaway boxes | AH17: =SUM(C17:AG17) -> 0
B18: Cups | Z18: 20 | AH18: =SUM(C18:AG18) -> 20
B19: Lids | AH19: =SUM(C19:AG19) -> 0
B20: Bags | AH20: =SUM(C20:AG20) -> 0
B21: Napkins | AH21: =SUM(C21:AG21) -> 0
B22: Disposable cutlery | AH22: =SUM(C22:AG22) -> 0
A23: 2-B | B23: Floor cleaner | AD23: 260 | AH23: =SUM(C23:AG23) -> 260
B24: Dishwashing liquid | AH24: =SUM(C24:AG24) -> 0
B25: Kitchen degreaser | AH25: =SUM(C25:AG25) -> 0
B26: Bathroom cleaner | AH26: =SUM(C26:AG26) -> 0
B27: Mops, brooms, brushes | AH27: =SUM(C27:AG27) -> 0
B28: Trash bags | AH28: =SUM(C28:AG28) -> 0
B29: Hand soap | AH29: =SUM(C29:AG29) -> 0
A30: 3 | B30: maintenance | AH30: =SUM(C30:AG30) -> 0
A31: 3-A | B31: Kitchen Equipment Maintenance | M31: 10 | AE31: 12 | AH31: =SUM(C31:AG31) -> 22
B32: Building Maintenance | C32: 1000 | AH32: =SUM(C32:AG32) -> 1000
B33: Electrical Repairs | AH33: =SUM(C33:AG33) -> 0
B34: Plumbing Repairs | AH34: =SUM(C34:AG34) -> 0
B35: (A/C) Maintenance | AH35: =SUM(C35:AG35) -> 0
B36: Furniture Repairs | AD36: 75 | AH36: =SUM(C36:AG36) -> 75
B37: pest control | D37: 1150 | AH37: =SUM(C37:AG37) -> 1150
B38: fire alarm | AH38: =SUM(C38:AG38) -> 0
A39: 4 | B39: car expenses | AH39: =SUM(C39:AG39) -> 0
A40: 4-A | B40: Car maintenance | P40: 1160 | AA40: =350+350+280+290 -> 1270 | AE40: 100 | AH40: =SUM(C40:AG40) -> 2530
...

Sheet Aug 2026
B1: =SUM(C154:AG154) -> 129385.29 | C1: 46235 | D1: 46236 | E1: 46237 | F1: 46238 | G1: 46239 | H1: 46240 | I1: 46241 | J1: 46242 | K1: 46243 | L1: 46244 | M1: 46245 | N1: 46246 | O1: 46247 | P1: 46248 | Q1: 46249 | R1: 46250 | S1: 46251 | T1: 46252 | U1: 46253 | V1: 46254 | W1: 46255 | X1: 46256 | Y1: 46257 | Z1: 46258 | AA1: 46259 | AB1: 46260 | AC1: 46261 | AD1: 46262 | AE1: 46263 | AF1: 46264 | AG1: 46265
A2: 1 | B2: Raw material | C2: =SUM(C3:C15) -> 1382.63 | D2: =SUM(D3:D15) -> 3663.54 | E2: =SUM(E3:E15) -> 2657.32 | F2: =SUM(F3:F15) -> 4816 | G2: =SUM(G3:G15) -> 1287.92 | H2: =SUM(H3:H15) -> 3450.6 | I2: =SUM(I3:I15) -> 34.75 | J2: =SUM(J3:J15) -> 938.22 | ... AG2: =SUM(AG3:AG15) -> 0 | AH2: =SUM(C2:AG2) -> 22795.49
A3: 1-A | B3: Food ingredients | C3: =110.68+407+99.75+30+164.85+163.35+57 -> 1032.63 | D3: =224+115+413.5+500+96+18 -> 1366.5 | E3: =32.89+443.7+20.25+9.28+2151.2 -> 2657.32 | F3: =16+30+10+760 -> 816 | G3: =5+37+450+12+506.92+96+16+31+39+95 -> 1287.92 | H3: =75+40+23+20+247.6+95+2950 -> 3450.6 | I3: 34.75 | J3: =515+35.09+20+182.13+186 -> 938.22 | K3: =68.68+35.32+30+415 -> 549 | L3: =28+25.5+95.78+48 -> 197.28 | M3: =130+76.75 -> 206.75 | N3: =46+49.25+224+120+124+950 -> 1513.25 | O3: =16.6+155.38+82.95+42.3+303.05+23.25+35 -> 658.53 | Q3: =30+26.5+52.5+149.65+760.5 -> 1019.15 | R3: =10 -> 10 | AH3: =SUM(C3:AG3) -> 15737.9
B4: Meat | D4: =2131.04+132 -> 2263.04 | L4: 184 | M4: 226.55 | AH4: =SUM(C4:AG4) -> 2673.59
B5: Chicken | AH5: =SUM(C5:AG5) -> 0
B6: Fish & seafood | AH6: =SUM(C6:AG6) -> 0
B7: Vegetables & fruits | D7: 34 | F7: 4000 | AH7: =SUM(C7:AG7) -> 4034
B8: Rice, flour, pasta | AH8: =SUM(C8:AG8) -> 0
B9: Dairy products | C9: 350 | AH9: =SUM(C9:AG9) -> 350
B10: Spices & seasonings | AH10: =SUM(C10:AG10) -> 0
A11: 1-B | B11: Beverages | AH11: =SUM(C11:AG11) -> 0
B12: Soft drinks | AH12: =SUM(C12:AG12) -> 0
B13: Juices | AH13: =SUM(C13:AG13) -> 0
B14: Coffee & tea | AH14: =SUM(C14:AG14) -> 0
B15: Water | AH15: =SUM(C15:AG15) -> 0
C16: =SUM(C17:C30) -> 0 | D16: =SUM(D17:D30) -> 0 | E16: =SUM(E17:E30) -> 0 | F16: =SUM(F17:F30) -> 6028 | G16: =SUM(G17:G30) -> 0 | H16: =SUM(H17:H30) -> 0 | I16: =SUM(I17:I30) -> 0 | J16: =SUM(J17:J30) -> 0 | ... AG16: =SUM(AG17:AG30) -> 0 | AH16: =SUM(C16:AG16) -> 7158
A17: 2 | B17: packaging | F17: =1398+5+4625 -> 6028 | K17: =145+230+41 -> 416 | L17: =50+185+138+21 -> 394 | N17: 110 | P17: 90 | Q17: =100+20 -> 120 | AH17: =SUM(C17:AG17) -> 7158
A18: 2-A | B18: Takeaway boxes | AH18: =SUM(C18:AG18) -> 0
B19: Cups | AH19: =SUM(C19:AG19) -> 0
B20: Lids | AH20: =SUM(C20:AG20) -> 0
B21: Bags | AH21: =SUM(C21:AG21) -> 0
B22: Napkins | AH22: =SUM(C22:AG22) -> 0
B23: Disposable cutlery | AH23: =SUM(C23:AG23) -> 0
A24: 2-B | B24: Floor cleaner | AH24: =SUM(C24:AG24) -> 0
B25: Dishwashing liquid | AH25: =SUM(C25:AG25) -> 0
B26: Kitchen degreaser | AH26: =SUM(C26:AG26) -> 0
B27: Bathroom cleaner | AH27: =SUM(C27:AG27) -> 0
B28: Mops, brooms, brushes | AH28: =SUM(C28:AG28) -> 0
B29: Trash bags | AH29: =SUM(C29:AG29) -> 0
B30: Hand soap | AH30: =SUM(C30:AG30) -> 0
C31: =SUM(C32:C40) -> 0 | D31: =SUM(D32:D40) -> 0 | E31: =SUM(E32:E40) -> 0 | F31: =SUM(F32:F40) -> 800 | G31: =SUM(G32:G40) -> 0 | H31: =SUM(H32:H40) -> 0 | I31: =SUM(I32:I40) -> 0 | J31: =SUM(J32:J40) -> 0 | ... AG31: =SUM(AG32:AG40) -> 0 | AH31: =SUM(C31:AG31) -> 1297
A32: 3 | B32: maintenance | AH32: =SUM(C32:AG32) -> 0
A33: 3-A | B33: Kitchen Equipment Maintenance | F33: 800 | O33: =7+25 -> 32 | AH33: =SUM(C33:AG33) -> 832
B34: Building Maintenance | K34: 465 | AH34: =SUM(C34:AG34) -> 465
B35: Electrical Repairs | AH35: =SUM(C35:AG35) -> 0
B36: Plumbing Repairs | AH36: =SUM(C36:AG36) -> 0
B37: (A/C) Maintenance | AH37: =SUM(C37:AG37) -> 0
B38: Furniture Repairs | AH38: =SUM(C38:AG38) -> 0
B39: pest control | AH39: =SUM(C39:AG39) -> 0
B40: fire alarm | AH40: =SUM(C40:AG40) -> 0
...

Sheet Aug Cost Analysis
B1: COST ANALYSIS - PARETO
B2: Pareto Chart for Cumulative Percent of Annual Costs across all Cost Centers is in cells B2 through E3.
B4: COST ANALYSIS
B5: Cost Center | C5: Monthly Cost | D5: Percent of Total | E5: Cumulative Percent
A6: 1 | B6: Raw Material | C6: ='Aug 2026'!E167 -> 22795.49 | D6: =IFERROR(Data[[#This Row],[Monthly Cost ]]/SUM(Data[[Monthly Cost ]]), "") -> 0.17632639 | E6: =IFERROR(SUM(INDEX(Data[Percent of Total],1):Data[[#This Row],[Percent of Total]]), "") -> 0.17632639
A7: 2 | B7: Packaging | C7: ='Aug 2026'!E168 -> 7158 | D7: =IFERROR(Data[[#This Row],[Monthly Cost ]]/SUM(Data[[Monthly Cost ]]), "") -> 0.055368159 | E7: =IFERROR(SUM(INDEX(Data[Percent of Total],1):Data[[#This Row],[Percent of Total]]), "") -> 0.23169455
A8: 3 | B8: Maintenance | C8: ='Aug 2026'!E169 -> 1297 | D8: =IFERROR(Data[[#This Row],[Monthly Cost ]]/SUM(Data[[Monthly Cost ]]), "") -> 0.010032481 | E8: =IFERROR(SUM(INDEX(Data[Percent of Total],1):Data[[#This Row],[Percent of Total]]), "") -> 0.24172703
A9: 4 | B9: Car Expenses | C9: ='Aug 2026'!E170 -> 1405 | D9: =IFERROR(Data[[#This Row],[Monthly Cost ]]/SUM(Data[[Monthly Cost ]]), "") -> 0.010867877 | E9: =IFERROR(SUM(INDEX(Data[Percent of Total],1):Data[[#This Row],[Percent of Total]]), "") -> 0.25259491
A10: 5 | B10: Car Rental and transportation | C10: ='Aug 2026'!E171 -> 6872.53 | D10: =IFERROR(Data[[#This Row],[Monthly Cost ]]/SUM(Data[[Monthly Cost ]]), "") -> 0.053160007 | E10: =IFERROR(SUM(INDEX(Data[Percent of Total],1):Data[[#This Row],[Percent of Total]]), "") -> 0.30575492
A11: 6 | B11: Direct expenses | C11: ='Aug 2026'!E172 -> 1240 | D11: =IFERROR(Data[[#This Row],[Monthly Cost ]]/SUM(Data[[Monthly Cost ]]), "") -> 0.0095915782 | E11: =IFERROR(SUM(INDEX(Data[Percent of Total],1):Data[[#This Row],[Percent of Total]]), "") -> 0.31534649
A12: 7 | B12: Rent | C12: ='Aug 2026'!E173 -> 12200 | D12: =IFERROR(Data[[#This Row],[Monthly Cost ]]/SUM(Data[[Monthly Cost ]]), "") -> 0.094368753 | E12: =IFERROR(SUM(INDEX(Data[Percent of Total],1):Data[[#This Row],[Percent of Total]]), "") -> 0.40971525
A13: 8 | B13: Salaries | C13: ='Aug 2026'!E174 -> 68935 | D13: =IFERROR(Data[[#This Row],[Monthly Cost ]]/SUM(Data[[Monthly Cost ]]), "") -> 0.53322213 | E13: =IFERROR(SUM(INDEX(Data[Percent of Total],1):Data[[#This Row],[Percent of Total]]), "") -> 0.94293738
A14: 9 | B14: Bonus and Allowance | C14: ='Aug 2026'!E175 -> 0 | D14: =IFERROR(Data[[#This Row],[Monthly Cost ]]/SUM(Data[[Monthly Cost ]]), "") -> 0 | E14: =IFERROR(SUM(INDEX(Data[Percent of Total],1):Data[[#This Row],[Percent of Total]]), "") -> 0.94293738
A15: 10 | B15: Marketing | C15: ='Aug 2026'!E176 -> 1116.56 | D15: =IFERROR(Data[[#This Row],[Monthly Cost ]]/SUM(Data[[Monthly Cost ]]), "") -> 0.0086367521 | E15: =IFERROR(SUM(INDEX(Data[Percent of Total],1):Data[[#This Row],[Percent of Total]]), "") -> 0.95157413
A16: 11 | B16: Kahramaa | C16: ='Aug 2026'!E177 -> 0 | D16: =IFERROR(Data[[#This Row],[Monthly Cost ]]/SUM(Data[[Monthly Cost ]]), "") -> 0 | E16: =IFERROR(SUM(INDEX(Data[Percent of Total],1):Data[[#This Row],[Percent of Total]]), "") -> 0.95157413
A17: 12 | B17: Bank Charges | C17: ='Aug 2026'!E178 -> 20 | D17: =IFERROR(Data[[#This Row],[Monthly Cost ]]/SUM(Data[[Monthly Cost ]]), "") -> 0.00015470287 | E17: =IFERROR(SUM(INDEX(Data[Percent of Total],1):Data[[#This Row],[Percent of Total]]), "") -> 0.95172884
... A24: 19 | B24: Other Expenses ( indirect ) | C24: ='Aug 2026'!E185 -> 14 | D24: =IFERROR(Data[[#This Row],[Monthly Cost ]]/SUM(Data[[Monthly Cost ]]), "") -> 0.00010829201 | E24: =IFERROR(SUM(INDEX(Data[Percent of Total],1):Data[[#This Row],[Percent of Total]]), "") -> 1
C25: ='Aug 2026'!E186 -> 0 | D25: =IFERROR(Data[[#This Row],[Monthly Cost ]]/SUM(Data[[Monthly Cost ]]), "") -> 0 | E25: =IFERROR(SUM(INDEX(Data[Percent of Total],1):Data[[#This Row],[Percent of Total]]), "") -> 1
C26: ='Aug 2026'!E187 -> 0 | D26: =IFERROR(Data[[#This Row],[Monthly Cost ]]/SUM(Data[[Monthly Cost ]]), "") -> 0 | E26: =IFERROR(SUM(INDEX(Data[Percent of Total],1):Data[[#This Row],[Percent of Total]]), "") -> 1
B27: Total | C27: =SUBTOTAL(109,Data[[Monthly Cost ]]) -> 129280.08 | D27: =SUBTOTAL(109,Data[Percent of Total]) -> 1
